<?xml version="1.0"?>
<robot name="diff_bot" xmlns:xacro="http://www.ros.org/wiki/xacro">

  <xacro:property name="wheel_radius" value="0.05"/>
  <xacro:property name="wheel_width" value="0.02"/>
  <xacro:property name="wheel_separation" value="0.20"/>

  <link name="base_link">
    <visual>
      <geometry>
        <box size="0.30 0.20 0.10"/>
      </geometry>
			<material name="black">
  			<color rgba="0 0 1 1"/>
			</material>
    </visual>
    <collision>
      <geometry>
        <box size="0.30 0.20 0.10"/>
      </geometry>
    </collision>
    <inertial>
      <mass value="2.0"/>
      <origin xyz="0 0 0"/>
      <inertia ixx="0.02" ixy="0" ixz="0" iyy="0.02" iyz="0" izz="0.02"/>
    </inertial>
  </link>

	<link name="left_wheel">
		<visual>
			<origin xyz="0 0 0" rpy="1.5707 0 0"/>
			<geometry>
				<cylinder radius="${wheel_radius}" length="${wheel_width}"/>
			</geometry>
			<material name="black">
  			<color rgba="0 0 0 1"/>
			</material>
		</visual>
		<collision>
			<origin xyz="0 0 0" rpy="1.5707 0 0"/>
			<geometry>
				<cylinder radius="${wheel_radius}" length="${wheel_width}"/>
			</geometry>
			<material name="black">
  			<color rgba="0 0 0 1"/>
			</material>
		</collision>
		<inertial>
			<mass value="0.2"/>
			<origin xyz="0 0 0"/>
			<inertia ixx="0.0005" ixy="0" ixz="0"
							iyy="0.0005" iyz="0"
							izz="0.0005"/>
		</inertial>
	</link>

	<link name="right_wheel">
		<visual>
			<origin xyz="0 0 0" rpy="1.5707 0 0"/>
			<geometry>
				<cylinder radius="${wheel_radius}" length="${wheel_width}"/>
			</geometry>
			<material name="black">
  			<color rgba="0 0 0 1"/>
			</material>
		</visual>
		<collision>
			<origin xyz="0 0 0" rpy="1.5707 0 0"/>
			<geometry>
				<cylinder radius="${wheel_radius}" length="${wheel_width}"/>
			</geometry>
			<material name="black">
  			<color rgba="0 0 0 1"/>
			</material>
		</collision>
		<inertial>
			<mass value="0.2"/>
			<origin xyz="0 0 0"/>
			<inertia ixx="0.0005" ixy="0" ixz="0"
							iyy="0.0005" iyz="0"
							izz="0.0005"/>
		</inertial>
	</link>

  <link name="caster_wheel">
    <visual>
      <geometry>
        <sphere radius="0.03"/>
      </geometry>
			<material name="black">
  			<color rgba="0 0 0 1"/>
			</material>
    </visual>
  </link>

  <link name="imu_link"/>

  <joint name="left_wheel_joint" type="continuous">
    <parent link="base_link"/>
    <child link="left_wheel"/>
    <origin xyz="0 ${wheel_separation/2} 0" rpy="0 1.5707 0"/>
    <axis xyz="0 0 1"/>
  </joint>

  <joint name="right_wheel_joint" type="continuous">
    <parent link="base_link"/>
    <child link="right_wheel"/>
    <origin xyz="0 -${wheel_separation/2} 0" rpy="0 1.5707 0"/>
    <axis xyz="0 0 1"/>
  </joint>

  <joint name="caster_joint" type="fixed">
    <parent link="base_link"/>
    <child link="caster_wheel"/>
    <origin xyz="-0.10 0 -0.05"/>
  </joint>

  <joint name="imu_joint" type="fixed">
    <parent link="base_link"/>
    <child link="imu_link"/>
    <origin xyz="0 0 0.05"/>
  </joint>

  <ros2_control name="DiffBotSystem" type="system">
    <hardware>
      <plugin>gazebo_ros2_control/GazeboSystem</plugin>
    </hardware>

    <joint name="left_wheel_joint">
      <command_interface name="velocity"/>
      <state_interface name="position"/>
      <state_interface name="velocity"/>
    </joint>

    <joint name="right_wheel_joint">
      <command_interface name="velocity"/>
      <state_interface name="position"/>
      <state_interface name="velocity"/>
    </joint>
  </ros2_control>

	<gazebo>
		<plugin filename="libgazebo_ros2_control.so"
						name="gazebo_ros2_control">
			<parameters>$(find bot_controls)/config/controllers.yaml</parameters>
		</plugin>
	</gazebo>

</robot>